<mujoco model="panda">
  <compiler angle="radian"/>

  <asset>
    <mesh name="link0" file="models/panda_description/meshes/visual/link0.stl"/>
    <mesh name="link1" file="models/panda_description/meshes/visual/link1.stl"/>
    <mesh name="link2" file="models/panda_description/meshes/visual/link2.stl"/>
    <mesh name="link3" file="models/panda_description/meshes/visual/link3.stl"/>
    <mesh name="link4" file="models/panda_description/meshes/visual/link4.stl"/>
    <mesh name="link5" file="models/panda_description/meshes/visual/link5.stl"/>
    <mesh name="link6" file="models/panda_description/meshes/visual/link6.stl"/>
    <mesh name="link7" file="models/panda_description/meshes/visual/link7.stl"/>
  </asset>

  <worldbody>
    <geom type="mesh" mesh="link0"/>
    <body name="panda_link1" pos="0 0 0.333">
      <inertial pos="0 0 0" mass="2.34" diaginertia="0.3 0.3 0.3"/>
      <joint name="panda_joint1" pos="0 0 0" axis="0 0 1" range="-2.8 2.8" actuatorfrcrange="-87 87"/>
      <geom type="mesh" mesh="link1"/>
      <body name="panda_link2" quat="0.707107 -0.707107 0 0">
        <inertial pos="0 0 0" mass="2.36" diaginertia="0.3 0.3 0.3"/>
        <joint name="panda_joint2" pos="0 0 0" axis="0 0 1" range="-1.65 1.65" actuatorfrcrange="-87 87"/>
        <geom type="mesh" mesh="link2"/>
        <body name="panda_link3" pos="0 -0.316 0" quat="0.707107 0.707107 0 0">
          <inertial pos="0 0 0" mass="2.38" diaginertia="0.3 0.3 0.3"/>
          <joint name="panda_joint3" pos="0 0 0" axis="0 0 1" range="-2.8 2.8" actuatorfrcrange="-87 87"/>
          <geom type="mesh" mesh="link3"/>
          <body name="panda_link4" pos="0.0825 0 0" quat="0.707107 0.707107 0 0">
            <inertial pos="0 0 0" mass="2.43" diaginertia="0.3 0.3 0.3"/>
            <joint name="panda_joint4" pos="0 0 0" axis="0 0 1" range="0.1 2.9" actuatorfrcrange="-87 87"/>
            <geom type="mesh" mesh="link4"/>
            <body name="panda_link5" pos="-0.0825 0.384 0" quat="0.707107 -0.707107 0 0">
              <inertial pos="0 0 0" mass="3.5" diaginertia="0.3 0.3 0.3"/>
              <joint name="panda_joint5" pos="0 0 0" axis="0 0 1" range="-2.8 2.8" actuatorfrcrange="-12 12"/>
              <geom type="mesh" mesh="link5"/>
              <body name="panda_link6" pos="0 0 0" quat="0.707107 0.707107 0 0">
                <inertial pos="0 0 0" mass="1.47" diaginertia="0.3 0.3 0.3"/>
                <joint name="panda_joint6" pos="0 0 0" axis="0 0 1" range="0.1 3.6" actuatorfrcrange="-12 12"/>
                <geom type="mesh" mesh="link6" quat="1 0 0 0"/>
                <body name="panda_link7" pos="0.088 0 0" quat="0.707107 0.707107 0 0">
                  <inertial pos="0 0 0" mass="0.45" diaginertia="0.3 0.3 0.3"/>
                  <joint name="panda_joint7" pos="0 0 0" axis="0 0 1" range="-2.8 2.8" actuatorfrcrange="-12 12"/>
                  <geom type="mesh" mesh="link7"/>
                </body>
              </body>
            </body>
          </body>
        </body>
      </body>
    </body>
  </worldbody>
</mujoco>
